Конструкция `try...catch` в JavaScript используется для обработки ошибок. Она позволяет выполнять код, который может вызвать исключение, и затем перехватывать и обрабатывать это исключение, не прерывая выполнение всей программы. Это особенно полезно для улучшения надёжности и стабильности вашего кода.

### Синтаксис конструкции `try...catch`

`try {   // Код, который может вызвать ошибку } catch (error) {   // Код для обработки ошибки }`

- **`try`**: Блок кода, в котором могут возникнуть ошибки. Если ошибка происходит, выполнение кода в блоке `catch` переходит сразу после возникновения ошибки.
- **`catch`**: Блок кода для обработки ошибок. Он выполняется только в том случае, если ошибка произошла в блоке `try`. Переменная `error` содержит информацию об ошибке.

### Пример использования

Рассмотрим простой пример, в котором мы пытаемся выполнить код, который может вызвать ошибку (например, деление на ноль):

`try {   const результат = 10 / 0; // Деление на ноль вызывает Infinity, но не ошибку   console.log(результат); } catch (error) {   console.error("Произошла ошибка:", error); }`

В этом примере, хотя деление на ноль не вызывает исключение (а возвращает `Infinity`), если бы была ошибка, например, попытка доступа к несуществующему свойству, код в блоке `catch` обработал бы её.

### Пример обработки реальной ошибки

`try {   const объект = null;   console.log(объект.свойство); // Это вызовет ошибку TypeError } catch (error) {   console.error("Произошла ошибка:", error.message); // Выводит сообщение об ошибке }`

В этом случае, попытка доступа к свойству `свойство` у `null` вызовет ошибку, которая будет поймана и обработана в блоке `catch`.

### Блок `finally`

В дополнение к блокам `try` и `catch`, вы можете использовать блок `finally`. Код внутри блока `finally` выполняется независимо от того, была ли ошибка или нет.

**Синтаксис:**

`try {   // Код, который может вызвать ошибку } catch (error) {   // Код для обработки ошибки } finally {   // Код, который выполнится в любом случае }`

**Пример использования:**

`try {   console.log("Попытка выполнения кода");   // Код, который может вызвать ошибку   const результат = 10 / 0;   console.log(результат); } catch (error) {   console.error("Произошла ошибка:", error.message); } finally {   console.log("Этот код выполнится в любом случае"); }`

**Результат:**

`Попытка выполнения кода Infinity Этот код выполнится в любом случае`

### Использование `throw` для создания ошибок

Вы также можете создавать собственные ошибки с помощью оператора `throw`.

**Пример использования:**

`function деление(a, b) {   if (b === 0) {     throw new Error("Деление на ноль не допускается!");   }   return a / b; }  try {   const результат = деление(10, 0); // Это вызовет ошибку   console.log(результат); } catch (error) {   console.error("Произошла ошибка:", error.message); }`

### Заключение

Конструкция `try...catch` является важным инструментом для обработки ошибок в JavaScript. Она помогает избежать прерывания выполнения программы при возникновении исключений и предоставляет возможность для выполнения кода, который всегда должен исполняться, используя блок `finally`. Понимание и использование `try...catch` помогает улучшить стабильность и надёжность вашего кода, делая его более устойчивым к непредвиденным ситуациям.